[2023-03-18 10:17:24,465] {taskinstance.py:1032} INFO - Dependencies all met for <TaskInstance: data_ingestion_gcs_dag_v3.0.download_dataset_task backfill__2021-01-02T06:00:00+00:00 [queued]>
[2023-03-18 10:17:24,740] {taskinstance.py:1032} INFO - Dependencies all met for <TaskInstance: data_ingestion_gcs_dag_v3.0.download_dataset_task backfill__2021-01-02T06:00:00+00:00 [queued]>
[2023-03-18 10:17:24,749] {taskinstance.py:1238} INFO -
--------------------------------------------------------------------------------
[2023-03-18 10:17:24,752] {taskinstance.py:1239} INFO - Starting attempt 2 of 3
[2023-03-18 10:17:24,755] {taskinstance.py:1240} INFO -
--------------------------------------------------------------------------------
[2023-03-18 10:17:24,967] {taskinstance.py:1259} INFO - Executing <Task(BashOperator): download_dataset_task> on 2021-01-02 06:00:00+00:00
[2023-03-18 10:17:25,032] {standard_task_runner.py:52} INFO - Started process 1879 to run task
[2023-03-18 10:17:25,096] {standard_task_runner.py:76} INFO - Running: ['***', 'tasks', 'run', 'data_ingestion_gcs_dag_v3.0', 'download_dataset_task', 'backfill__2021-01-02T06:00:00+00:00', '--job-id', '156', '--pool', 'default_pool', '--raw', '--subdir', 'DAGS_FOLDER/dag.py', '--cfg-path', '/tmp/tmpb75db25m', '--error-file', '/tmp/tmprhdy0o2h']
[2023-03-18 10:17:25,110] {standard_task_runner.py:77} INFO - Job 156: Subtask download_dataset_task
[2023-03-18 10:17:25,809] {logging_mixin.py:109} INFO - Running <TaskInstance: data_ingestion_gcs_dag_v3.0.download_dataset_task backfill__2021-01-02T06:00:00+00:00 [running]> on host 8cface6de844
[2023-03-18 10:17:26,280] {logging_mixin.py:109} WARNING - /home/***/.local/lib/python3.7/site-packages/***/utils/context.py:152 AirflowContextDeprecationWarning: Accessing 'execution_date' from the template is deprecated and will be removed in a future version. Please use 'data_interval_start' or 'logical_date' instead.
[2023-03-18 10:17:26,424] {taskinstance.py:1426} INFO - Exporting the following env vars:
AIRFLOW_CTX_DAG_OWNER=***
AIRFLOW_CTX_DAG_ID=data_ingestion_gcs_dag_v3.0
AIRFLOW_CTX_TASK_ID=download_dataset_task
AIRFLOW_CTX_EXECUTION_DATE=2021-01-02T06:00:00+00:00
AIRFLOW_CTX_DAG_RUN_ID=backfill__2021-01-02T06:00:00+00:00
[2023-03-18 10:17:26,441] {subprocess.py:62} INFO - Tmp dir root location:
 /tmp
[2023-03-18 10:17:26,448] {subprocess.py:74} INFO - Running command: ['bash', '-c', 'curl -sSLf https://github.com/DataTalksClub/nyc-tlc-data/releases/download/yellow/yellow_tripdata_2021-01.csv.gz > /opt/***/yellow_tripdata_2021-01.csv']
[2023-03-18 10:17:26,509] {subprocess.py:85} INFO - Output:
[2023-03-18 10:17:42,422] {subprocess.py:89} INFO - curl: (6) Could not resolve host: github.com
[2023-03-18 10:17:42,508] {subprocess.py:93} INFO - Command exited with return code 6
[2023-03-18 10:17:42,694] {taskinstance.py:1700} ERROR - Task failed with exception
Traceback (most recent call last):
  File "/home/airflow/.local/lib/python3.7/site-packages/airflow/models/taskinstance.py", line 1329, in _run_raw_task
    self._execute_task_with_callbacks(context)
  File "/home/airflow/.local/lib/python3.7/site-packages/airflow/models/taskinstance.py", line 1455, in _execute_task_with_callbacks
    result = self._execute_task(context, self.task)
  File "/home/airflow/.local/lib/python3.7/site-packages/airflow/models/taskinstance.py", line 1511, in _execute_task
    result = execute_callable(context=context)
  File "/home/airflow/.local/lib/python3.7/site-packages/airflow/operators/bash.py", line 188, in execute
    f'Bash command failed. The command returned a non-zero exit code {result.exit_code}.'
airflow.exceptions.AirflowException: Bash command failed. The command returned a non-zero exit code 6.
[2023-03-18 10:17:42,816] {taskinstance.py:1277} INFO - Marking task as UP_FOR_RETRY. dag_id=data_ingestion_gcs_dag_v3.0, task_id=download_dataset_task, execution_date=20210102T060000, start_date=20230318T101724, end_date=20230318T101742
[2023-03-18 10:17:42,986] {standard_task_runner.py:92} ERROR - Failed to execute job 156 for task download_dataset_task
Traceback (most recent call last):
  File "/home/airflow/.local/lib/python3.7/site-packages/airflow/task/task_runner/standard_task_runner.py", line 85, in _start_by_fork
    args.func(args, dag=self.dag)
  File "/home/airflow/.local/lib/python3.7/site-packages/airflow/cli/cli_parser.py", line 48, in command
    return func(*args, **kwargs)
  File "/home/airflow/.local/lib/python3.7/site-packages/airflow/utils/cli.py", line 92, in wrapper
    return f(*args, **kwargs)
  File "/home/airflow/.local/lib/python3.7/site-packages/airflow/cli/commands/task_command.py", line 298, in task_run
    _run_task_by_selected_method(args, dag, ti)
  File "/home/airflow/.local/lib/python3.7/site-packages/airflow/cli/commands/task_command.py", line 107, in _run_task_by_selected_method
    _run_raw_task(args, ti)
  File "/home/airflow/.local/lib/python3.7/site-packages/airflow/cli/commands/task_command.py", line 184, in _run_raw_task
    error_file=args.error_file,
  File "/home/airflow/.local/lib/python3.7/site-packages/airflow/utils/session.py", line 70, in wrapper
    return func(*args, session=session, **kwargs)
  File "/home/airflow/.local/lib/python3.7/site-packages/airflow/models/taskinstance.py", line 1329, in _run_raw_task
    self._execute_task_with_callbacks(context)
  File "/home/airflow/.local/lib/python3.7/site-packages/airflow/models/taskinstance.py", line 1455, in _execute_task_with_callbacks
    result = self._execute_task(context, self.task)
  File "/home/airflow/.local/lib/python3.7/site-packages/airflow/models/taskinstance.py", line 1511, in _execute_task
    result = execute_callable(context=context)
  File "/home/airflow/.local/lib/python3.7/site-packages/airflow/operators/bash.py", line 188, in execute
    f'Bash command failed. The command returned a non-zero exit code {result.exit_code}.'
airflow.exceptions.AirflowException: Bash command failed. The command returned a non-zero exit code 6.
[2023-03-18 10:17:43,077] {local_task_job.py:154} INFO - Task exited with return code 1
[2023-03-18 10:17:43,470] {local_task_job.py:264} INFO - 0 downstream tasks scheduled from follow-on schedule check
