[2023-03-18 10:07:10,727] {taskinstance.py:1032} INFO - Dependencies all met for <TaskInstance: data_ingestion_gcs_dag_v3.0.download_dataset_task backfill__2021-02-02T06:00:00+00:00 [queued]>
[2023-03-18 10:07:10,782] {taskinstance.py:1032} INFO - Dependencies all met for <TaskInstance: data_ingestion_gcs_dag_v3.0.download_dataset_task backfill__2021-02-02T06:00:00+00:00 [queued]>
[2023-03-18 10:07:10,784] {taskinstance.py:1238} INFO - 
--------------------------------------------------------------------------------
[2023-03-18 10:07:10,786] {taskinstance.py:1239} INFO - Starting attempt 1 of 2
[2023-03-18 10:07:10,794] {taskinstance.py:1240} INFO - 
--------------------------------------------------------------------------------
[2023-03-18 10:07:10,862] {taskinstance.py:1259} INFO - Executing <Task(BashOperator): download_dataset_task> on 2021-02-02 06:00:00+00:00
[2023-03-18 10:07:10,882] {standard_task_runner.py:52} INFO - Started process 966 to run task
[2023-03-18 10:07:10,899] {standard_task_runner.py:76} INFO - Running: ['***', 'tasks', 'run', 'data_ingestion_gcs_dag_v3.0', 'download_dataset_task', 'backfill__2021-02-02T06:00:00+00:00', '--job-id', '150', '--pool', 'default_pool', '--raw', '--subdir', 'DAGS_FOLDER/dag.py', '--cfg-path', '/tmp/tmp8nmzwm6o', '--error-file', '/tmp/tmp8jwouo8q']
[2023-03-18 10:07:10,905] {standard_task_runner.py:77} INFO - Job 150: Subtask download_dataset_task
[2023-03-18 10:07:11,187] {logging_mixin.py:109} INFO - Running <TaskInstance: data_ingestion_gcs_dag_v3.0.download_dataset_task backfill__2021-02-02T06:00:00+00:00 [running]> on host 8cface6de844
[2023-03-18 10:07:11,388] {logging_mixin.py:109} WARNING - /home/***/.local/lib/python3.7/site-packages/***/utils/context.py:152 AirflowContextDeprecationWarning: Accessing 'execution_date' from the template is deprecated and will be removed in a future version. Please use 'data_interval_start' or 'logical_date' instead.
[2023-03-18 10:07:11,485] {taskinstance.py:1426} INFO - Exporting the following env vars:
AIRFLOW_CTX_DAG_OWNER=***
AIRFLOW_CTX_DAG_ID=data_ingestion_gcs_dag_v3.0
AIRFLOW_CTX_TASK_ID=download_dataset_task
AIRFLOW_CTX_EXECUTION_DATE=2021-02-02T06:00:00+00:00
AIRFLOW_CTX_DAG_RUN_ID=backfill__2021-02-02T06:00:00+00:00
[2023-03-18 10:07:11,490] {subprocess.py:62} INFO - Tmp dir root location: 
 /tmp
[2023-03-18 10:07:11,497] {subprocess.py:74} INFO - Running command: ['bash', '-c', 'curl -sSLf https://github.com/DataTalksClub/nyc-tlc-data/releases/download/yellow/yellow_tripdata_2021-02.csv.gz > /opt/***/yellow_tripdata_2021-02.csv']
[2023-03-18 10:07:11,544] {subprocess.py:85} INFO - Output:
[2023-03-18 10:12:13,620] {subprocess.py:89} INFO - curl: (92) HTTP/2 stream 0 was not closed cleanly: PROTOCOL_ERROR (err 1)
[2023-03-18 10:12:13,726] {subprocess.py:93} INFO - Command exited with return code 92
[2023-03-18 10:12:13,951] {taskinstance.py:1700} ERROR - Task failed with exception
Traceback (most recent call last):
  File "/home/airflow/.local/lib/python3.7/site-packages/airflow/models/taskinstance.py", line 1329, in _run_raw_task
    self._execute_task_with_callbacks(context)
  File "/home/airflow/.local/lib/python3.7/site-packages/airflow/models/taskinstance.py", line 1455, in _execute_task_with_callbacks
    result = self._execute_task(context, self.task)
  File "/home/airflow/.local/lib/python3.7/site-packages/airflow/models/taskinstance.py", line 1511, in _execute_task
    result = execute_callable(context=context)
  File "/home/airflow/.local/lib/python3.7/site-packages/airflow/operators/bash.py", line 188, in execute
    f'Bash command failed. The command returned a non-zero exit code {result.exit_code}.'
airflow.exceptions.AirflowException: Bash command failed. The command returned a non-zero exit code 92.
[2023-03-18 10:12:14,016] {taskinstance.py:1277} INFO - Marking task as UP_FOR_RETRY. dag_id=data_ingestion_gcs_dag_v3.0, task_id=download_dataset_task, execution_date=20210202T060000, start_date=20230318T100710, end_date=20230318T101214
[2023-03-18 10:12:14,143] {standard_task_runner.py:92} ERROR - Failed to execute job 150 for task download_dataset_task
Traceback (most recent call last):
  File "/home/airflow/.local/lib/python3.7/site-packages/airflow/task/task_runner/standard_task_runner.py", line 85, in _start_by_fork
    args.func(args, dag=self.dag)
  File "/home/airflow/.local/lib/python3.7/site-packages/airflow/cli/cli_parser.py", line 48, in command
    return func(*args, **kwargs)
  File "/home/airflow/.local/lib/python3.7/site-packages/airflow/utils/cli.py", line 92, in wrapper
    return f(*args, **kwargs)
  File "/home/airflow/.local/lib/python3.7/site-packages/airflow/cli/commands/task_command.py", line 298, in task_run
    _run_task_by_selected_method(args, dag, ti)
  File "/home/airflow/.local/lib/python3.7/site-packages/airflow/cli/commands/task_command.py", line 107, in _run_task_by_selected_method
    _run_raw_task(args, ti)
  File "/home/airflow/.local/lib/python3.7/site-packages/airflow/cli/commands/task_command.py", line 184, in _run_raw_task
    error_file=args.error_file,
  File "/home/airflow/.local/lib/python3.7/site-packages/airflow/utils/session.py", line 70, in wrapper
    return func(*args, session=session, **kwargs)
  File "/home/airflow/.local/lib/python3.7/site-packages/airflow/models/taskinstance.py", line 1329, in _run_raw_task
    self._execute_task_with_callbacks(context)
  File "/home/airflow/.local/lib/python3.7/site-packages/airflow/models/taskinstance.py", line 1455, in _execute_task_with_callbacks
    result = self._execute_task(context, self.task)
  File "/home/airflow/.local/lib/python3.7/site-packages/airflow/models/taskinstance.py", line 1511, in _execute_task
    result = execute_callable(context=context)
  File "/home/airflow/.local/lib/python3.7/site-packages/airflow/operators/bash.py", line 188, in execute
    f'Bash command failed. The command returned a non-zero exit code {result.exit_code}.'
airflow.exceptions.AirflowException: Bash command failed. The command returned a non-zero exit code 92.
[2023-03-18 10:12:14,278] {local_task_job.py:154} INFO - Task exited with return code 1
[2023-03-18 10:12:14,467] {local_task_job.py:264} INFO - 0 downstream tasks scheduled from follow-on schedule check
